Traceback (most recent call last):
  File "/Users/mmccull/opt/anaconda3/lib/python3.9/site-packages/jupyter_cache/executors/utils.py", line 58, in single_nb_execution
    executenb(
  File "/Users/mmccull/opt/anaconda3/lib/python3.9/site-packages/nbclient/client.py", line 1204, in execute
    return NotebookClient(nb=nb, resources=resources, km=km, **kwargs).execute()
  File "/Users/mmccull/opt/anaconda3/lib/python3.9/site-packages/nbclient/util.py", line 84, in wrapped
    return just_run(coro(*args, **kwargs))
  File "/Users/mmccull/opt/anaconda3/lib/python3.9/site-packages/nbclient/util.py", line 62, in just_run
    return loop.run_until_complete(coro)
  File "/Users/mmccull/opt/anaconda3/lib/python3.9/asyncio/base_events.py", line 647, in run_until_complete
    return future.result()
  File "/Users/mmccull/opt/anaconda3/lib/python3.9/site-packages/nbclient/client.py", line 663, in async_execute
    await self.async_execute_cell(
  File "/Users/mmccull/opt/anaconda3/lib/python3.9/site-packages/nbclient/client.py", line 965, in async_execute_cell
    await self._check_raise_for_error(cell, cell_index, exec_reply)
  File "/Users/mmccull/opt/anaconda3/lib/python3.9/site-packages/nbclient/client.py", line 862, in _check_raise_for_error
    raise CellExecutionError.from_cell_and_msg(cell, exec_reply_content)
nbclient.exceptions.CellExecutionError: An error occurred while executing the following cell:
------------------
# fit T and h
# quantum spectral distribution function
def quantumB_fit_t_H(x,h,T):
    return 2*h*c**2/(x*nm_to_m)**5/(np.exp(h*c/(x*nm_to_m*kB*T))-1)

from scipy.optimize import curve_fit

p0 = np.array([1e-34,5000])
popt, pcov = curve_fit(quantumB_fit_t_H, solar[:,0], solar[:,3]*1E13,p0=p0)
print(popt)

h = 6.62607015E-34 
def quantumB_fit_T(x,T):
    return 2*h*c**2/(x*nm_to_m)**5/(np.exp(h*c/(x*nm_to_m*kB*T))-1)

p0 = np.array([5000])
popt, pcov = curve_fit(quantumB_fit_T, solar[:,0], solar[:,3]*1E13,p0=p0)
print(popt)
------------------

[0;31m---------------------------------------------------------------------------[0m
[0;31mNameError[0m                                 Traceback (most recent call last)
[0;32m/var/folders/td/dll8n_kj4vd0zxjm0xd9m7740000gq/T/ipykernel_86929/3122538737.py[0m in [0;36m<module>[0;34m[0m
[1;32m      7[0m [0;34m[0m[0m
[1;32m      8[0m [0mp0[0m [0;34m=[0m [0mnp[0m[0;34m.[0m[0marray[0m[0;34m([0m[0;34m[[0m[0;36m1e-34[0m[0;34m,[0m[0;36m5000[0m[0;34m][0m[0;34m)[0m[0;34m[0m[0;34m[0m[0m
[0;32m----> 9[0;31m [0mpopt[0m[0;34m,[0m [0mpcov[0m [0;34m=[0m [0mcurve_fit[0m[0;34m([0m[0mquantumB_fit_t_H[0m[0;34m,[0m [0msolar[0m[0;34m[[0m[0;34m:[0m[0;34m,[0m[0;36m0[0m[0;34m][0m[0;34m,[0m [0msolar[0m[0;34m[[0m[0;34m:[0m[0;34m,[0m[0;36m3[0m[0;34m][0m[0;34m*[0m[0;36m1E13[0m[0;34m,[0m[0mp0[0m[0;34m=[0m[0mp0[0m[0;34m)[0m[0;34m[0m[0;34m[0m[0m
[0m[1;32m     10[0m [0mprint[0m[0;34m([0m[0mpopt[0m[0;34m)[0m[0;34m[0m[0;34m[0m[0m
[1;32m     11[0m [0;34m[0m[0m

[0;31mNameError[0m: name 'solar' is not defined
NameError: name 'solar' is not defined

