Traceback (most recent call last):
  File "/Users/mmccull/opt/anaconda3/lib/python3.9/site-packages/jupyter_cache/executors/utils.py", line 58, in single_nb_execution
    executenb(
  File "/Users/mmccull/opt/anaconda3/lib/python3.9/site-packages/nbclient/client.py", line 1204, in execute
    return NotebookClient(nb=nb, resources=resources, km=km, **kwargs).execute()
  File "/Users/mmccull/opt/anaconda3/lib/python3.9/site-packages/nbclient/util.py", line 84, in wrapped
    return just_run(coro(*args, **kwargs))
  File "/Users/mmccull/opt/anaconda3/lib/python3.9/site-packages/nbclient/util.py", line 62, in just_run
    return loop.run_until_complete(coro)
  File "/Users/mmccull/opt/anaconda3/lib/python3.9/asyncio/base_events.py", line 647, in run_until_complete
    return future.result()
  File "/Users/mmccull/opt/anaconda3/lib/python3.9/site-packages/nbclient/client.py", line 663, in async_execute
    await self.async_execute_cell(
  File "/Users/mmccull/opt/anaconda3/lib/python3.9/site-packages/nbclient/client.py", line 965, in async_execute_cell
    await self._check_raise_for_error(cell, cell_index, exec_reply)
  File "/Users/mmccull/opt/anaconda3/lib/python3.9/site-packages/nbclient/client.py", line 862, in _check_raise_for_error
    raise CellExecutionError.from_cell_and_msg(cell, exec_reply_content)
nbclient.exceptions.CellExecutionError: An error occurred while executing the following cell:
------------------
# inverse
np.linalg.inv(a)
------------------

[0;31m---------------------------------------------------------------------------[0m
[0;31mLinAlgError[0m                               Traceback (most recent call last)
[0;32m/var/folders/td/dll8n_kj4vd0zxjm0xd9m7740000gq/T/ipykernel_84972/1624788978.py[0m in [0;36m<module>[0;34m[0m
[1;32m      1[0m [0;31m# inverse[0m[0;34m[0m[0;34m[0m[0m
[0;32m----> 2[0;31m [0mnp[0m[0;34m.[0m[0mlinalg[0m[0;34m.[0m[0minv[0m[0;34m([0m[0ma[0m[0;34m)[0m[0;34m[0m[0;34m[0m[0m
[0m
[0;32m~/opt/anaconda3/lib/python3.9/site-packages/numpy-1.25.0-py3.9-macosx-10.9-x86_64.egg/numpy/linalg/linalg.py[0m in [0;36minv[0;34m(a)[0m
[1;32m    559[0m     [0msignature[0m [0;34m=[0m [0;34m'D->D'[0m [0;32mif[0m [0misComplexType[0m[0;34m([0m[0mt[0m[0;34m)[0m [0;32melse[0m [0;34m'd->d'[0m[0;34m[0m[0;34m[0m[0m
[1;32m    560[0m     [0mextobj[0m [0;34m=[0m [0mget_linalg_error_extobj[0m[0;34m([0m[0m_raise_linalgerror_singular[0m[0;34m)[0m[0;34m[0m[0;34m[0m[0m
[0;32m--> 561[0;31m     [0mainv[0m [0;34m=[0m [0m_umath_linalg[0m[0;34m.[0m[0minv[0m[0;34m([0m[0ma[0m[0;34m,[0m [0msignature[0m[0;34m=[0m[0msignature[0m[0;34m,[0m [0mextobj[0m[0;34m=[0m[0mextobj[0m[0;34m)[0m[0;34m[0m[0;34m[0m[0m
[0m[1;32m    562[0m     [0;32mreturn[0m [0mwrap[0m[0;34m([0m[0mainv[0m[0;34m.[0m[0mastype[0m[0;34m([0m[0mresult_t[0m[0;34m,[0m [0mcopy[0m[0;34m=[0m[0;32mFalse[0m[0;34m)[0m[0;34m)[0m[0;34m[0m[0;34m[0m[0m
[1;32m    563[0m [0;34m[0m[0m

[0;32m~/opt/anaconda3/lib/python3.9/site-packages/numpy-1.25.0-py3.9-macosx-10.9-x86_64.egg/numpy/linalg/linalg.py[0m in [0;36m_raise_linalgerror_singular[0;34m(err, flag)[0m
[1;32m    110[0m [0;34m[0m[0m
[1;32m    111[0m [0;32mdef[0m [0m_raise_linalgerror_singular[0m[0;34m([0m[0merr[0m[0;34m,[0m [0mflag[0m[0;34m)[0m[0;34m:[0m[0;34m[0m[0;34m[0m[0m
[0;32m--> 112[0;31m     [0;32mraise[0m [0mLinAlgError[0m[0;34m([0m[0;34m"Singular matrix"[0m[0;34m)[0m[0;34m[0m[0;34m[0m[0m
[0m[1;32m    113[0m [0;34m[0m[0m
[1;32m    114[0m [0;32mdef[0m [0m_raise_linalgerror_nonposdef[0m[0;34m([0m[0merr[0m[0;34m,[0m [0mflag[0m[0;34m)[0m[0;34m:[0m[0;34m[0m[0;34m[0m[0m

[0;31mLinAlgError[0m: Singular matrix
LinAlgError: Singular matrix

